<?xml version="1.0"?>
<robot name="tank_bot">

  <!-- Robot Base -->
  <link name="base_link">
    <visual>
      <geometry>
        <box size="0.60 0.40 0.15"/>
      </geometry>
      <material name="DarkGrey">
        <color rgba="0.3 0.3 0.3 1.0"/>
      </material>
    </visual>
    <collision>
      <geometry>
        <box size="0.60 0.40 0.15"/>
      </geometry>
    </collision>
    <inertial>
      <origin xyz="0 0 0" rpy="0 0 0"/>      
      <mass value="15"/>
      <inertia ixx="0.3125" ixy="0.0" ixz="0.0" iyy="0.5208" iyz="0.0" izz="0.5833"/>
    </inertial>
  </link>
  
  <!-- Robot Footprint -->
  <link name="base_footprint">
    <inertial>
      <origin xyz="0 0 0" rpy="0 0 0"/>      
      <mass value="0.001"/>
      <inertia ixx="0.0000001" ixy="0.0" ixz="0.0" iyy="0.0000001" iyz="0.0" izz="0.0000001"/>
    </inertial>
  </link>

  <joint name="base_joint" type="fixed">
    <parent link="base_link"/>
    <child link="base_footprint"/>
    <origin xyz="0.0 0.0 -0.085" rpy="0 0 0"/>
  </joint>

  <!-- Track System - Left Side -->
  <!-- Front Left Wheel/Sprocket -->
  <link name="left_front_wheel_link">
    <visual>
      <origin xyz="0 0 0" rpy="1.5707 0 0"/>
      <geometry>
        <cylinder radius="0.075" length="0.05"/>
      </geometry>
      <material name="DarkGrey">
        <color rgba="0.2 0.2 0.2 1.0"/>
      </material>
    </visual>
    <collision>
      <origin xyz="0 0 0" rpy="1.5707 0 0"/>
      <geometry>
        <cylinder radius="0.075" length="0.05"/>
      </geometry>
    </collision>
    <inertial>
      <mass value="1.0"/>
      <inertia ixx="0.0021" ixy="0.0" ixz="0.0" iyy="0.0021" iyz="0.0" izz="0.0035"/>
    </inertial>
  </link>

  <joint name="left_front_wheel_joint" type="continuous">
    <parent link="base_link"/>
    <child link="left_front_wheel_link"/>
    <origin xyz="0.25 0.225 -0.05" rpy="0 0 0"/>
    <axis xyz="0 1 0"/>
  </joint>

  <!-- Rear Left Wheel/Idler -->
  <link name="left_rear_wheel_link">
    <visual>
      <origin xyz="0 0 0" rpy="1.5707 0 0"/>
      <geometry>
        <cylinder radius="0.075" length="0.05"/>
      </geometry>
      <material name="DarkGrey">
        <color rgba="0.2 0.2 0.2 1.0"/>
      </material>
    </visual>
    <collision>
      <origin xyz="0 0 0" rpy="1.5707 0 0"/>
      <geometry>
        <cylinder radius="0.075" length="0.05"/>
      </geometry>
    </collision>
    <inertial>
      <mass value="1.0"/>
      <inertia ixx="0.0021" ixy="0.0" ixz="0.0" iyy="0.0021" iyz="0.0" izz="0.0035"/>
    </inertial>
  </link>

  <joint name="left_rear_wheel_joint" type="continuous">
    <parent link="base_link"/>
    <child link="left_rear_wheel_link"/>
    <origin xyz="-0.25 0.225 -0.05" rpy="0 0 0"/>
    <axis xyz="0 1 0"/>
  </joint>

  <!-- Left Track -->
  <link name="left_track_link">
    <visual>
      <geometry>
        <mesh>
          <scale>0.6 0.1 0.15</scale>
          <uri>file://meshes/track.dae</uri>
        </mesh>
      </geometry>
      <material name="Black">
        <color rgba="0.1 0.1 0.1 1.0"/>
      </material>
    </visual>
    <collision>
      <geometry>
        <box size="0.60 0.10 0.15"/>
      </geometry>
    </collision>
    <inertial>
      <mass value="5.0"/>
      <inertia ixx="0.0104" ixy="0.0" ixz="0.0" iyy="0.1563" iyz="0.0" izz="0.1563"/>
    </inertial>
  </link>

  <joint name="left_track_joint" type="fixed">
    <parent link="base_link"/>
    <child link="left_track_link"/>
    <origin xyz="0 0.225 -0.05" rpy="0 0 0"/>
  </joint>

  <!-- Track System - Right Side -->
  <!-- Front Right Wheel/Sprocket -->
  <link name="right_front_wheel_link">
    <visual>
      <origin xyz="0 0 0" rpy="1.5707 0 0"/>
      <geometry>
        <cylinder radius="0.075" length="0.05"/>
      </geometry>
      <material name="DarkGrey">
        <color rgba="0.2 0.2 0.2 1.0"/>
      </material>
    </visual>
    <collision>
      <origin xyz="0 0 0" rpy="1.5707 0 0"/>
      <geometry>
        <cylinder radius="0.075" length="0.05"/>
      </geometry>
    </collision>
    <inertial>
      <mass value="1.0"/>
      <inertia ixx="0.0021" ixy="0.0" ixz="0.0" iyy="0.0021" iyz="0.0" izz="0.0035"/>
    </inertial>
  </link>

  <joint name="right_front_wheel_joint" type="continuous">
    <parent link="base_link"/>
    <child link="right_front_wheel_link"/>
    <origin xyz="0.25 -0.225 -0.05" rpy="0 0 0"/>
    <axis xyz="0 1 0"/>
  </joint>

  <!-- Rear Right Wheel/Idler -->
  <link name="right_rear_wheel_link">
    <visual>
      <origin xyz="0 0 0" rpy="1.5707 0 0"/>
      <geometry>
        <cylinder radius="0.075" length="0.05"/>
      </geometry>
      <material name="DarkGrey">
        <color rgba="0.2 0.2 0.2 1.0"/>
      </material>
    </visual>
    <collision>
      <origin xyz="0 0 0" rpy="1.5707 0 0"/>
      <geometry>
        <cylinder radius="0.075" length="0.05"/>
      </geometry>
    </collision>
    <inertial>
      <mass value="1.0"/>
      <inertia ixx="0.0021" ixy="0.0" ixz="0.0" iyy="0.0021" iyz="0.0" izz="0.0035"/>
    </inertial>
  </link>

  <joint name="right_rear_wheel_joint" type="continuous">
    <parent link="base_link"/>
    <child link="right_rear_wheel_link"/>
    <origin xyz="-0.25 -0.225 -0.05" rpy="0 0 0"/>
    <axis xyz="0 1 0"/>
  </joint>

  <!-- Right Track -->
  <link name="right_track_link">
    <visual>
      <geometry>
        <mesh>
          <scale>0.6 0.1 0.15</scale>
          <uri>file://meshes/track.dae</uri>
        </mesh>
      </geometry>
      <material name="Black">
        <color rgba="0.1 0.1 0.1 1.0"/>
      </material>
    </visual>
    <collision>
      <geometry>
        <box size="0.60 0.10 0.15"/>
      </geometry>
    </collision>
    <inertial>
      <mass value="5.0"/>
      <inertia ixx="0.0104" ixy="0.0" ixz="0.0" iyy="0.1563" iyz="0.0" izz="0.1563"/>
    </inertial>
  </link>

  <joint name="right_track_joint" type="fixed">
    <parent link="base_link"/>
    <child link="right_track_link"/>
    <origin xyz="0 -0.225 -0.05" rpy="0 0 0"/>
  </joint>

  <!-- Depth Camera -->
  <link name="camera_link">
    <visual>
      <origin xyz="0 0 0" rpy="0 0 0"/>
      <geometry>
        <box size="0.05 0.05 0.05"/>
      </geometry>
      <material name="Blue">
        <color rgba="0.0 0.0 0.8 1.0"/>
      </material>
    </visual>
    <collision>
      <origin xyz="0 0 0" rpy="0 0 0"/>
      <geometry>
        <box size="0.05 0.05 0.05"/>
      </geometry>
    </collision>
    <inertial>
      <mass value="0.1"/>
      <inertia ixx="0.000042" ixy="0.0" ixz="0.0" iyy="0.000042" iyz="0.0" izz="0.000042"/>
    </inertial>
  </link>

  <joint name="camera_joint" type="fixed">
    <parent link="base_link"/>
    <child link="camera_link"/>
    <origin xyz="0.25 0 0.1" rpy="0 0 0"/>
  </joint>

  <!-- Shovel -->
  <link name="shovel_link">
    <visual>
      <origin xyz="0.025 0 -0.075" rpy="0 0 0"/>
      <geometry>
        <box size="0.05 0.45 0.15"/>
      </geometry>
      <material name="Orange">
        <color rgba="1.0 0.5 0.0 1.0"/>
      </material>
    </visual>
    <collision>
      <origin xyz="0.025 0 -0.075" rpy="0 0 0"/>
      <geometry>
        <box size="0.05 0.45 0.15"/>
      </geometry>
    </collision>
    <inertial>
      <mass value="2.0"/>
      <inertia ixx="0.0104" ixy="0.0" ixz="0.0" iyy="0.0021" iyz="0.0" izz="0.0104"/>
    </inertial>
  </link>

  <joint name="shovel_joint" type="prismatic">
    <parent link="base_link"/>
    <child link="shovel_link"/>
    <origin xyz="0.325 0 0" rpy="0 0 0"/>
    <axis xyz="1 0 0"/>
    <limit lower="0" upper="0.3" effort="100" velocity="0.1"/>
  </joint>

  <!-- Gazebo plugins for simulation -->
  <gazebo>
    <plugin name="gazebo_ros_control" filename="libgazebo_ros_control.so">
      <robotNamespace>/tank_bot</robotNamespace>
      <robotSimType>gazebo_ros_control/DefaultRobotHWSim</robotSimType>
    </plugin>
  </gazebo>
  
  <!-- Track controllers for differential drive -->
  <gazebo>
    <plugin name="differential_drive_controller" filename="libgazebo_ros_diff_drive.so">
      <updateRate>50</updateRate>
      <leftJoint>left_track_joint</leftJoint>
      <rightJoint>right_track_joint</rightJoint>
      <wheelSeparation>0.45</wheelSeparation>
      <wheelDiameter>0.15</wheelDiameter>
      <wheelAcceleration>1.0</wheelAcceleration>
      <wheelTorque>50</wheelTorque>
      <commandTopic>cmd_vel</commandTopic>
      <odometryTopic>odom</odometryTopic>
      <odometryFrame>odom</odometryFrame>
      <robotBaseFrame>base_link</robotBaseFrame>
      <publishWheelTF>false</publishWheelTF>
      <publishOdomTF>true</publishOdomTF>
      <publishWheelJointState>false</publishWheelJointState>
      <legacyMode>false</legacyMode>
      <odometrySource>world</odometrySource>
      <publishTf>true</publishTf>
    </plugin>
  </gazebo>

  <!-- Depth camera plugin -->
  <gazebo reference="camera_link">
    <sensor type="depth" name="camera">
      <update_rate>30.0</update_rate>
      <camera name="head">
        <horizontal_fov>1.3962634</horizontal_fov>
        <image>
          <width>640</width>
          <height>480</height>
          <format>R8G8B8</format>
        </image>
        <clip>
          <near>0.02</near>
          <far>300</far>
        </clip>
        <noise>
          <type>gaussian</type>
          <mean>0.0</mean>
          <stddev>0.007</stddev>
        </noise>
      </camera>
      <plugin name="camera_controller" filename="libgazebo_ros_openni_kinect.so">
        <baseline>0.2</baseline>
        <alwaysOn>true</alwaysOn>
        <updateRate>0.0</updateRate>
        <cameraName>camera</cameraName>
        <imageTopicName>rgb/image_raw</imageTopicName>
        <cameraInfoTopicName>rgb/camera_info</cameraInfoTopicName>
        <depthImageTopicName>depth/image_raw</depthImageTopicName>
        <depthImageInfoTopicName>depth/camera_info</depthImageInfoTopicName>
        <pointCloudTopicName>depth/points</pointCloudTopicName>
        <frameName>camera_link</frameName>
        <pointCloudCutoff>0.5</pointCloudCutoff>
        <pointCloudCutoffMax>3.0</pointCloudCutoffMax>
        <distortionK1>0.00000001</distortionK1>
        <distortionK2>0.00000001</distortionK2>
        <distortionK3>0.00000001</distortionK3>
        <distortionT1>0.00000001</distortionT1>
        <distortionT2>0.00000001</distortionT2>
      </plugin>
    </sensor>
  </gazebo>

  <!-- Material properties for better visualization -->
  <gazebo reference="base_link">
    <material>Gazebo/DarkGrey</material>
  </gazebo>
  
  <gazebo reference="left_track_link">
    <material>Gazebo/Black</material>
    <mu1>1.0</mu1>
    <mu2>1.0</mu2>
    <kp>1000000.0</kp>
    <kd>100.0</kd>
    <minDepth>0.001</minDepth>
    <maxVel>1.0</maxVel>
    <fdir1>1 0 0</fdir1>
  </gazebo>
  
  <gazebo reference="right_track_link">
    <material>Gazebo/Black</material>
    <mu1>1.0</mu1>
    <mu2>1.0</mu2>
    <kp>1000000.0</kp>
    <kd>100.0</kd>
    <minDepth>0.001</minDepth>
    <maxVel>1.0</maxVel>
    <fdir1>1 0 0</fdir1>
  </gazebo>
</robot>
